Workbook

Sheet REP TYT
A1: TOYOTASERVICIOS S.A. | N1: Página: | P1: 1 | Q1: de | S1: 2
A2: REPUESTOS | N2: Fecha: | P2: Thu Mar 12 2026 17:46:49 GMT-0500 (hora de Ecuador)
N3: KMOYOLEMA
A4: TIPO DOCUMENTO: F% TODOS LOS TIPOS DE FACTURA
A5: CLIENTE: % TODOS LOS CLIENTES | P5: MARGEN
F6: FECHA FINAL: 28/02/2026
A7: FECHA INICIAL: 01/02/2026
A9: AN | B9: BODEGA | C9: FECHA | E9: # DOC | F9: SERIE | G9: DESCRIPCION | H9: AUTORIZACION | I9: RUC | J9: N° Cliente | K9: CLIENTE | M9: CLIENTE PUBLICO | P9: ITEM | R9: SUBTOT | T9: DESC | V9: NETO | W9: SIN IVA | X9: CON IVA | Y9: ECOVALOR | Z9: VAL. IVA | AA9: OTR.CAR | AB9: TRANSP | AC9: INTERES | AD9: TOT FAC | AE9: ANTICIPO | AF9: SALDO | AG9: COSTO | AH9: UTILIDAD | AI9: VENTA | AJ9: COSTO | AK9: SERIE FISICO | AL9: ASIENTO | AM9: AGENCIA | AN9: FORMA PAGO
A11: NO | B11: MATR | C11: 02/02/2026 | E11: 000014861 | F11: 001-505 | G11: FACTURA CONTADO | H11: 0202202601189171221500120015050000148615658032318 | I11: 18XXXXXXX5001 | J11: 112549 | K11: ytDI^56S"|LQf=>[*%TYnEFc2-\av | M11: NO | P11: 1 | R11: 3.7 | T11: 0 | V11: 3.7 | W11: 0 | X11: 3.7 | Y11: 0 | Z11: 0.56 | AA11: 0 | AB11: 0 | AC11: 0 | AD11: 4.26 | AE11: 0 | AF11: 0 | AG11: 2.7745122 | AH11: 0.925488 | AI11: 25.013187 | AJ11: 33.35678 | AK11: 1 | AL11: 361 | AM11: 01 | AN11: CONTADO
A12: NO | B12: MATR | C12: 02/02/2026 | E12: 000014862 | F12: 001-505 | G12: FACTURA CONTADO | H12: 0202202601189171221500120015050000148625658032313 | I12: 18XXXXXXX7 | J12: 102770 | K12: %QNl3KOx-YVt;SW!5a^|C[_)=i | M12: NO | P12: 1 | R12: 31.32 | T12: 0 | V12: 31.32 | W12: 0 | X12: 31.32 | Y12: 0 | Z12: 4.7 | AA12: 0 | AB12: 0 | AC12: 0 | AD12: 36.02 | AE12: 0 | AF12: 0 | AG12: 23.488026 | AH12: 7.831974 | AI12: 25.006304 | AJ12: 33.34454 | AK12: 1 | AL12: 361 | AM12: 01 | AN12: CONTADO
A13: NO | B13: MATR | C13: 03/02/2026 | E13: 000014863 | F13: 001-505 | G13: FACTURA CONTADO | H13: 0302202601189171221500120015050000148635658032313 | I13: 18XXXXXXX5001 | J13: 151828 | K13: Ird!>}n[Qzl)F&vcY#t1N.~ka | M13: NO | P13: 1 | R13: 38.86 | T13: 0 | V13: 38.86 | W13: 0 | X13: 38.86 | Y13: 0 | Z13: 5.83 | AA13: 0 | AB13: 0 | AC13: 0 | AD13: 44.69 | AE13: 0 | AF13: 0 | AG13: 29.144286 | AH13: 9.715715 | AI13: 25.001842 | AJ13: 33.336605 | AK13: 1 | AL13: 362 | AM13: 01 | AN13: CONTADO
A14: NO | B14: MATR | C14: 03/02/2026 | E14: 000014864 | F14: 001-505 | G14: FACTURA CONTADO | H14: 0302202601189171221500120015050000148645658032319 | I14: 18XXXXXXX5 | J14: 151790 | K14: #bD8`Z^w+jL@hbf 3rTHpj | M14: NO | P14: 1 | R14: 83.44 | T14: 0 | V14: 83.44 | W14: 0 | X14: 83.44 | Y14: 0 | Z14: 12.52 | AA14: 0 | AB14: 0 | AC14: 0 | AD14: 95.96 | AE14: 95.96 | AF14: 0 | AG14: 62.58 | AH14: 20.86 | AI14: 25 | AJ14: 33.333336 | AK14: 1 | AL14: 362 | AM14: 01 | AN14: CONTADO
A15: NO | B15: MATR | C15: 04/02/2026 | E15: 000014865 | F15: 001-505 | G15: FACTURA CONTADO | H15: 0402202601189171221500120015050000148655658032319 | I15: 18XXXXXXX2 | J15: 101712 | K15: X+8!NF.H`3@)VN6Ph;H1^V>XpCP | M15: NO | P15: 2 | R15: 214.7 | T15: 0 | V15: 214.7 | W15: 0 | X15: 214.7 | Y15: 0 | Z15: 32.21 | AA15: 0 | AB15: 0 | AC15: 0 | AD15: 246.91 | AE15: 246.91 | AF15: 0 | AG15: 161.02 | AH15: 53.679993 | AI15: 25.002325 | AJ15: 33.337467 | AK15: 1 | AL15: 363 | AM15: 01 | AN15: CONTADO
A16: NO | B16: MATR | C16: 04/02/2026 | E16: 000014866 | F16: 001-505 | G16: FACTURA CONTADO | H16: 0402202601189171221500120015050000148665658032314 | I16: 18XXXXXXX4 | J16: 134569 | K16: 6fV+0f-7>n^38n5?Fvf;@v=GN~ | M16: NO | P16: 3 | R16: 133.74 | T16: 0 | V16: 133.74 | W16: 0 | X16: 133.74 | Y16: 0 | Z16: 20.06 | AA16: 0 | AB16: 0 | AC16: 0 | AD16: 153.8 | AE16: 153.8 | AF16: 0 | AG16: 100.29 | AH16: 33.450005 | AI16: 25.011217 | AJ16: 33.35328 | AK16: 1 | AL16: 363 | AM16: 01 | AN16: CONTADO
A17: NO | B17: MATR | C17: 04/02/2026 | E17: 000014867 | F17: 001-505 | G17: FACTURA CONTADO | H17: 0402202601189171221500120015050000148675658032311 | I17: 02XXXXXXX3 | J17: 151867 | K17: Ug*j|VMd]o2r%^Ulew:z-f] | M17: NO | P17: 2 | R17: 386.34 | T17: 19.31 | V17: 367.03 | W17: 0 | X17: 367.03 | Y17: 0 | Z17: 55.05 | AA17: 0 | AB17: 0 | AC17: 0 | AD17: 422.08 | AE17: 0 | AF17: 0 | AG17: 289.75504 | AH17: 77.27496 | AI17: 21.054129 | AJ17: 26.669067 | AK17: 1 | AL17: 363 | AM17: 01 | AN17: CONTADO
A18: NO | B18: MATR | C18: 05/02/2026 | E18: 000014868 | F18: 001-505 | G18: FACTURA CONTADO | H18: 0502202601189171221500120015050000148685658032311 | I18: 18XXXXXXX1 | J18: 151888 | K18: [5emfl"Ic=munt*QkEu}v|2YsM}&~% | M18: NO | P18: 1 | R18: 38.86 | T18: 0 | V18: 38.86 | W18: 0 | X18: 38.86 | Y18: 0 | Z18: 5.83 | AA18: 0 | AB18: 0 | AC18: 0 | AD18: 44.69 | AE18: 0 | AF18: 0 | AG18: 29.145 | AH18: 9.715 | AI18: 25 | AJ18: 33.333336 | AK18: 1 | AL18: 364 | AM18: 01 | AN18: CONTADO
A19: NO | B19: MATR | C19: 05/02/2026 | E19: 000014869 | F19: 001-505 | G19: FACTURA CONTADO | H19: 0502202601189171221500120015050000148695658032315 | I19: 18XXXXXXX0001 | J19: 151311 | K19: =)&VKr^fE1.^SzfnM96f[#nvU | M19: NO | P19: 1 | R19: 149.52 | T19: 0 | V19: 149.52 | W19: 0 | X19: 149.52 | Y19: 0 | Z19: 22.43 | AA19: 0 | AB19: 0 | AC19: 0 | AD19: 171.95 | AE19: 0 | AF19: 0 | AG19: 112.14 | AH19: 37.380005 | AI19: 25.000004 | AJ19: 33.333336 | AK19: 1 | AL19: 364 | AM19: 01 | AN19: CONTADO
A20: NO | B20: MATR | C20: 06/02/2026 | E20: 000014872 | F20: 001-505 | G20: FACTURA CONTADO | H20: 0602202601189171221500120015050000148725658032316 | I20: 18XXXXXXX0 | J20: 1561 | K20: ^uDR?&nXf}LZG.v`n&TbO6~hv.\j | M20: NO | P20: 2 | R20: 434.55 | T20: 0 | V20: 434.55 | W20: 0 | X20: 434.55 | Y20: 0 | Z20: 65.18 | AA20: 0 | AB20: 0 | AC20: 0 | AD20: 499.73 | AE20: 499.73 | AF20: 0 | AG20: 325.91 | AH20: 108.63998 | AI20: 25.000572 | AJ20: 33.33435 | AK20: 1 | AL20: 365 | AM20: 01 | AN20: CONTADO
A21: NO | B21: MATR | C21: 06/02/2026 | E21: 000014873 | F21: 001-505 | G21: FACTURA CONTADO | H21: 0602202601189171221500120015050000148735658032311 | I21: 16XXXXXXX9 | J21: 151896 | K21: *<"Tm[[L2D*\uccT:L2d}kk\B | M21: NO | P21: 2 | R21: 90.03 | T21: 0 | V21: 90.03 | W21: 0 | X21: 90.03 | Y21: 0 | Z21: 13.5 | AA21: 0 | AB21: 0 | AC21: 0 | AD21: 103.53 | AE21: 103.53 | AF21: 0 | AG21: 67.5225 | AH21: 22.5075 | AI21: 25 | AJ21: 33.333336 | AK21: 1 | AL21: 365 | AM21: 01 | AN21: CONTADO
A22: NO | B22: MATR | C22: 06/02/2026 | E22: 000014874 | F22: 001-505 | G22: FACTURA CONTADO | H22: 0602202601189171221500120015050000148745658032317 | I22: 05XXXXXXX3001 | J22: 151894 | K22: \-jE:xW\d5rMB!_dl=zUJ)gltE#]R | M22: NO | P22: 1 | R22: 275.64 | T22: 0 | V22: 275.64 | W22: 0 | X22: 275.64 | Y22: 0 | Z22: 41.35 | AA22: 0 | AB22: 0 | AC22: 0 | AD22: 316.99 | AE22: 0 | AF22: 0 | AG22: 206.73 | AH22: 68.91002 | AI22: 25.000006 | AJ22: 33.333344 | AK22: 1 | AL22: 365 | AM22: 01 | AN22: CONTADO
... A48: NO | B48: MATR | C48: 23/02/2026 | E48: 000014905 | F48: 001-505 | G48: FACTURA CONTADO | H48: 2302202601189171221500120015050000149055658032318 | I48: 17XXXXXXX4001 | J48: 37438 | K48: IMKvP;;+QUS~XCC3Y]['`KK;aec/hS | M48: NO | P48: 2 | R48: 77.47 | T48: 11.62 | V48: 65.85 | W48: 0 | X48: 65.85 | Y48: 0 | Z48: 9.88 | AA48: 0 | AB48: 0 | AC48: 0 | AD48: 75.73 | AE48: 0 | AF48: 0 | AG48: 58.099033 | AH48: 7.750965 | AI48: 11.770638 | AJ48: 13.340953 | AK48: 1 | AL48: 376 | AM48: 01 | AN48: CONTADO
A49: AN | B49: BODEGA | C49: FECHA | E49: # DOC | F49: SERIE | G49: DESCRIPCION | H49: AUTORIZACION | I49: RUC | J49: N° Cliente | K49: CLIENTE | M49: CLIENTE PUBLICO | P49: ITEM | R49: SUBTOT | T49: DESC | V49: NETO | W49: SIN IVA | X49: CON IVA | Y49: ECOVALOR | Z49: VAL. IVA | AA49: OTR.CAR | AB49: TRANSP | AC49: INTERES | AD49: TOT FAC | AE49: ANTICIPO | AF49: SALDO | AG49: COSTO | AH49: UTILIDAD | AI49: VENTA | AJ49: COSTO | AK49: SERIE FISICO | AL49: ASIENTO | AM49: AGENCIA | AN49: FORMA PAGO
A51: NO | B51: MATR | C51: 24/02/2026 | E51: 000014908 | F51: 001-505 | G51: FACTURA CONTADO | H51: 2402202601189171221500120015050000149085658032319 | I51: 18XXXXXXX5001 | J51: 152048 | K51: ;DCG|J^OCLKO%RfWKTSW-Zn_S\[_5b | M51: NO | P51: 1 | R51: 130.43 | T51: 0 | V51: 130.43 | W51: 0 | X51: 130.43 | Y51: 0 | Z51: 19.56 | AA51: 0 | AB51: 0 | AC51: 0 | AD51: 149.99 | AE51: 0 | AF51: 0 | AG51: 80 | AH51: 50.429993 | AI51: 38.664417 | AJ51: 63.03749 | AK51: 1 | AL51: 377 | AM51: 01 | AN51: CONTADO
A52: NO | B52: MATR | C52: 24/02/2026 | E52: 000014909 | F52: 001-505 | G52: FACTURA CONTADO | H52: 2402202601189171221500120015050000149095658032314 | I52: 18XXXXXXX5 | J52: 152185 | K52: =AN&D*/GEIV.L27OMQ^6T:?WUYf> | M52: NO | P52: 2 | R52: 53.91 | T52: 0 | V52: 53.91 | W52: 0 | X52: 53.91 | Y52: 0 | Z52: 8.09 | AA52: 0 | AB52: 0 | AC52: 0 | AD52: 62 | AE52: 0 | AF52: 0 | AG52: 40.435 | AH52: 13.474998 | AI52: 24.99536 | AJ52: 33.325085 | AK52: 1 | AL52: 377 | AM52: 01 | AN52: CONTADO
A53: NO | B53: MATR | C53: 24/02/2026 | E53: 000014910 | F53: 001-505 | G53: FACTURA CONTADO | H53: 2402202601189171221500120015050000149105658032311 | I53: 18XXXXXXX1001 | J53: 144071 | K53: n)'v]7CYv1/~e?Ka~97'mGSi'A?/u | M53: NO | P53: 2 | R53: 225 | T53: 0 | V53: 225 | W53: 0 | X53: 225 | Y53: 0 | Z53: 33.75 | AA53: 0 | AB53: 0 | AC53: 0 | AD53: 258.75 | AE53: 258.75 | AF53: 0 | AG53: 168.74 | AH53: 56.259995 | AI53: 25.00444 | AJ53: 33.341232 | AK53: 1 | AL53: 377 | AM53: 01 | AN53: CONTADO
A54: NO | B54: MATR | C54: 24/02/2026 | E54: 000014911 | F54: 001-505 | G54: FACTURA CONTADO | H54: 2402202601189171221500120015050000149115658032315 | I54: 18XXXXXXX6001 | J54: 50358 | K54: _t1OTovTg|9W\w~\o%A_d 'dw-I | M54: NO | P54: 3 | R54: 355.26 | T54: 35.53 | V54: 319.73 | W54: 0 | X54: 319.73 | Y54: 0 | Z54: 47.96 | AA54: 0 | AB54: 0 | AC54: 0 | AD54: 367.69 | AE54: 0 | AF54: 0 | AG54: 266.44 | AH54: 53.29001 | AI54: 16.66719 | AJ54: 20.000753 | AK54: 1 | AL54: 377 | AM54: 01 | AN54: CONTADO
A55: NO | B55: MATR | C55: 25/02/2026 | E55: 000014915 | F55: 001-505 | G55: FACTURA CONTADO | H55: 2502202601189171221500120015050000149155658032311 | I55: 18XXXXXXX7 | J55: 43329 | K55: gbH0+^#RojP83f+ZwrX@;n3b z`HCv | M55: NO | P55: 1 | R55: 48.04 | T55: 0 | V55: 48.04 | W55: 0 | X55: 48.04 | Y55: 0 | Z55: 7.21 | AA55: 0 | AB55: 0 | AC55: 0 | AD55: 55.25 | AE55: 0 | AF55: 0 | AG55: 36.029996 | AH55: 12.010006 | AI55: 25.000011 | AJ55: 33.333355 | AK55: 1 | AL55: 378 | AM55: 01 | AN55: CONTADO
A56: NO | B56: MATR | C56: 25/02/2026 | E56: 000014916 | F56: 001-505 | G56: FACTURA CONTADO | H56: 2502202601189171221500120015050000149165658032317 | I56: 18XXXXXXX8 | J56: 152169 | K56: (_:'X*>V0gB/`2F^8oJ7h:Nf@wR?pB | M56: NO | P56: 3 | R56: 257.04 | T56: 0 | V56: 257.04 | W56: 0 | X56: 257.04 | Y56: 0 | Z56: 38.56 | AA56: 0 | AB56: 0 | AC56: 0 | AD56: 295.6 | AE56: 295.6 | AF56: 0 | AG56: 192.78 | AH56: 64.26001 | AI56: 25.000004 | AJ56: 33.333336 | AK56: 1 | AL56: 378 | AM56: 01 | AN56: CONTADO
A57: NO | B57: MATR | C57: 25/02/2026 | E57: 000014917 | F57: 001-505 | G57: FACTURA CONTADO | H57: 2502202601189171221500120015050000149175658032312 | I57: 18XXXXXXX2 | J57: 5738 | K57: ug+(LaSc}o30Ti[k&w | M57: NO | P57: 1 | R57: 9.28 | T57: 0 | V57: 9.28 | W57: 0 | X57: 9.28 | Y57: 0 | Z57: 1.39 | AA57: 0 | AB57: 0 | AC57: 0 | AD57: 10.67 | AE57: 0 | AF57: 0 | AG57: 6.96 | AH57: 2.3199997 | AI57: 24.999996 | AJ57: 33.33333 | AK57: 1 | AL57: 378 | AM57: 01 | AN57: CONTADO
A58: NO | B58: MATR | C58: 26/02/2026 | E58: 000014920 | F58: 001-505 | G58: FACTURA CONTADO | H58: 2602202601189171221500120015050000149205658032313 | I58: 02XXXXXXX7 | J58: 124727 | K58: JpXT*X\`Rx`\2`dhZ!hd:hl | M58: NO | P58: 1 | R58: 15 | T58: 0 | V58: 15 | W58: 0 | X58: 15 | Y58: 0 | Z58: 2.25 | AA58: 0 | AB58: 0 | AC58: 0 | AD58: 17.25 | AE58: 17.25 | AF58: 0 | AG58: 6.26 | AH58: 8.74 | AI58: 58.266663 | AJ58: 139.61661 | AK58: 1 | AL58: 379 | AM58: 01 | AN58: CONTADO
A59: NO | B59: MATR | C59: 26/02/2026 | E59: 000014921 | F59: 001-505 | G59: FACTURA CONTADO | H59: 2602202601189171221500120015050000149215658032319 | I59: 18XXXXXXX5 | J59: 48789 | K59: @xhC3S0"H!pK;[8*P)xSCc@2X1![ | M59: NO | P59: 1 | R59: 24.02 | T59: 3.6 | V59: 20.42 | W59: 0 | X59: 20.42 | Y59: 0 | Z59: 3.06 | AA59: 0 | AB59: 0 | AC59: 0 | AD59: 23.48 | AE59: 0 | AF59: 0 | AG59: 19.513562 | AH59: 0.9064388 | AI59: 4.4389753 | AJ59: 4.6451735 | AK59: 1 | AL59: 379 | AM59: 01 | AN59: CONTADO
A60: NO | B60: MATR | C60: 26/02/2026 | E60: 000014922 | F60: 001-505 | G60: FACTURA CONTADO | H60: 2602202601189171221500120015050000149225658032314 | I60: 05XXXXXXX3 | J60: 39593 | K60: !jAKL3YB)rIST;aJ1zQ[\CiR9#YcdK | M60: NO | P60: 1 | R60: 253.12 | T60: 0 | V60: 253.12 | W60: 0 | X60: 253.12 | Y60: 0 | Z60: 37.97 | AA60: 0 | AB60: 0 | AC60: 0 | AD60: 291.09 | AE60: 291.09 | AF60: 0 | AG60: 189.84 | AH60: 63.28 | AI60: 25 | AJ60: 33.333336 | AK60: 1 | AL60: 379 | AM60: 01 | AN60: CONTADO
A61: NO | B61: MATR | C61: 27/02/2026 | E61: 000014928 | F61: 001-505 | G61: FACTURA CONTADO | H61: 2702202601189171221500120015050000149285658032311 | I61: 17XXXXXXX9001 | J61: 152218 | K61: kK#HG^]?sS+POfeG | M61: NO | P61: 1 | R61: 26.71 | T61: 0 | V61: 26.71 | W61: 0 | X61: 26.71 | Y61: 0 | Z61: 4.01 | AA61: 0 | AB61: 0 | AC61: 0 | AD61: 30.72 | AE61: 30.72 | AF61: 0 | AG61: 20.03 | AH61: 6.6799984 | AI61: 25.009356 | AJ61: 33.349968 | AK61: 1 | AL61: 380 | AM61: 01 | AN61: CONTADO
A62: NO | B62: MATR | C62: 27/02/2026 | E62: 000014929 | F62: 001-505 | G62: FACTURA CONTADO | H62: 2702202601189171221500120015050000149295658032317 | I62: 18XXXXXXX1001 | J62: 148183 | K62: SU%)P-XC[]-1X5`Kce59`=hSkm= | M62: NO | P62: 1 | R62: 57.6 | T62: 0 | V62: 57.6 | W62: 0 | X62: 57.6 | Y62: 0 | Z62: 8.64 | AA62: 0 | AB62: 0 | AC62: 0 | AD62: 66.24 | AE62: 66.24 | AF62: 0 | AG62: 43.2 | AH62: 14.399998 | AI62: 24.999996 | AJ62: 33.33333 | AK62: 1 | AL62: 380 | AM62: 01 | AN62: CONTADO
... A85: NO | B85: MATR | C85: 27/02/2026 | E85: 000014932 | F85: 001-505 | G85: FACTURA CREDITO | H85: 2702202601189171221500120015050000149325658032313 | I85: 18XXXXXXX8001 | J85: 906 | K85: &/P"ZU[*.7X*b]c26?`2jek:>Gh:rm | M85: NO | P85: 2 | R85: 621.11 | T85: 0 | V85: 621.11 | W85: 0 | X85: 621.11 | Y85: 0 | Z85: 93.17 | AA85: 0 | AB85: 0 | AC85: 0 | AD85: 714.28 | AE85: 0 | AF85: 0 | AG85: 539.88244 | AH85: 81.22754 | AI85: 13.077803 | AJ85: 15.045412 | AK85: 1 | AL85: 380 | AM85: 01 | AN85: CREDITO
L87: TOTAL GENERAL: | P87: 17626.15 | R87: 274.09 | T87: 17352.06 | V87: 0 | W87: 17352.06 | X87: 2602.83 | Y87: 0 | AA87: 0 | AB87: 19954.89 | AC87: 0 | AD87: 0 | AE87: 5633.43 | AF87: 14292.947 | AG87: 14292.947 | AH87: 3059.1135 | AI87: 17.629683 | AJ87: 21.402956
N88: MAYOR | P88: =+'MY REP TYT'!I38 | R88: =+'MY REP TYT'!H53

Sheet NC REP TYT
B1: TOYOTASERVICIOS S.A. | F1: DEVOLUCIÓN DE VENTAS
B2: REPUESTOS | AC2: Fecha: | AE2: 46085.73
B3: FECHA INICIAL: 01/02/2026
AC4: RepLibroDevolucionesGeneralCB
A5: FECHA FINAL: 28/02/2026
A7: ANULADA | C7: BODEGA | D7: FECHA NC | E7: CODIGO | G7: AGENCIA | H7: SERIE | I7: N/C No. | J7: DEV. A FAC. | K7: DESCRIPCION | L7: AUTORIZACION | N7: FECHA FACT | O7: TOt FACT | P7: CEDULA | R7: COD CLI | T7: CLIENTE | U7: CLIENTE PUBLICO | V7: ITEM | W7: SUBTOT | X7: DESC | Y7: NETO | Z7: SIN IVA | AA7: CON IVA | AB7: ECOVALOR | AD7: VAL. IVA | AF7: OTR.CAR | AG7: INTERES | AH7: TRANSPORTE | AJ7: TOT. NC | AK7: ANTICIPO | AL7: S/NOTA CR | AM7: COSTO | AN7: UTILIDAD | AO7: ASIENTO | AP7: FORMA PAGO
AF8: 0 | AG8: 0 | AH8: 0 | AJ8: 967.79 | AK8: 0 | AM8: 664.38 | AN8: 303.40997 | AO8: 372 | AP8: CONTADO
M9: TOTAL GENERAL: | V9: 0 | W9: 0 | X9: 0 | Y9: 0 | Z9: 0 | AA9: 0 | AB9: 0 | AD9: 0 | AG9: 0 | AH9: 0 | AJ9: 967.79 | AK9: 0 | AM9: 664.38 | AN9: 303.40997
V10: MAYOR | W10: =+'MY REP TYT'!H57 -> 885.86 | X10: =+'MY REP TYT'!I53 -> 44.3

Sheet MY REP TYT
A1: CUENTA | B1: NOMBRE | C1: N/M | D1: FECHA | E1: TIPO | F1: NO. | G1: DETALLE | H1: DEBITO | I1: CREDITO | J1: SALDO
A2: 04.01.01.01.0001 | B2: VTAS RPTOS TOYOTA - CONTADO CON IVA | C2: N | D2: 46055.208 | E2: REPTO | F2: 361 | G2: MOD. REPUESTOS REP01 | H2: 0 | I2: 35.02 | J2: -9056.76
A3: 04.01.01.01.0001 | B3: VTAS RPTOS TOYOTA - CONTADO CON IVA | C3: N | D3: 46056.208 | E3: REPTO | F3: 362 | G3: MOD. REPUESTOS REP01 | H3: 0 | I3: 122.3 | J3: -9179.06
A4: 04.01.01.01.0001 | B4: VTAS RPTOS TOYOTA - CONTADO CON IVA | C4: N | D4: 46057.208 | E4: REPTO | F4: 363 | G4: MOD. REPUESTOS REP01 | H4: 0 | I4: 734.78 | J4: -9913.84
A5: 04.01.01.01.0001 | B5: VTAS RPTOS TOYOTA - CONTADO CON IVA | C5: N | D5: 46058.208 | E5: REPTO | F5: 364 | G5: MOD. REPUESTOS REP01 | H5: 0 | I5: 188.38 | J5: -10102.22
A6: 04.01.01.01.0001 | B6: VTAS RPTOS TOYOTA - CONTADO CON IVA | C6: N | D6: 46059.208 | E6: REPTO | F6: 365 | G6: MOD. REPUESTOS REP01 | H6: 0 | I6: 916.66 | J6: -11018.88
A7: 04.01.01.01.0001 | B7: VTAS RPTOS TOYOTA - CONTADO CON IVA | C7: N | D7: 46060.208 | E7: REPTO | F7: 366 | G7: MOD. REPUESTOS REP01 | H7: 0 | I7: 251.32 | J7: -11270.2
A8: 04.01.01.01.0001 | B8: VTAS RPTOS TOYOTA - CONTADO CON IVA | C8: N | D8: 46062.208 | E8: REPTO | F8: 367 | G8: MOD. REPUESTOS REP01 | H8: 0 | I8: 157.63 | J8: -11427.83
A9: 04.01.01.01.0001 | B9: VTAS RPTOS TOYOTA - CONTADO CON IVA | C9: N | D9: 46063.208 | E9: REPTO | F9: 368 | G9: MOD. REPUESTOS REP01 | H9: 0 | I9: 13.21 | J9: -11441.04
A10: 04.01.01.01.0001 | B10: VTAS RPTOS TOYOTA - CONTADO CON IVA | C10: N | D10: 46063.208 | E10: REPTO | F10: 368 | G10: MOD. REPUESTOS REP01 | H10: 0 | I10: 583.18 | J10: -12024.22
A11: 04.01.01.01.0001 | B11: VTAS RPTOS TOYOTA - CONTADO CON IVA | C11: N | D11: 46064.208 | E11: REPTO | F11: 369 | G11: MOD. REPUESTOS REP01 | H11: 0 | I11: 871.15 | J11: -12895.37
A12: 04.01.01.01.0001 | B12: VTAS RPTOS TOYOTA - CONTADO CON IVA | C12: N | D12: 46065.208 | E12: REPTO | F12: 370 | G12: MOD. REPUESTOS REP01 | H12: 0 | I12: 49.54 | J12: -12944.91
A13: 04.01.01.01.0001 | B13: VTAS RPTOS TOYOTA - CONTADO CON IVA | C13: N | D13: 46066.208 | E13: REPTO | F13: 371 | G13: MOD. REPUESTOS REP01 | H13: 0 | I13: 74.34 | J13: -13019.25
... A37: 04.01.01.01.0003 | B37: VTAS RPTOS TOYOTA - CREDITO CON IVA | C37: N | D37: 46080.208 | E37: REPTO | F37: 380 | G37: MOD. REPUESTOS REP01 | H37: 0 | I37: 4347.77 | J37: -20280.94
H38: =SUM(H2:H37) -> 0 | I38: =SUM(I2:I37) -> 17626.15
A42: 04.01.01.01.0005 | B42: DESC VTAS RPTOS TOYOTA CONTADO CON IVA | C42: N | D42: 46057.208 | E42: REPTO | F42: 363 | G42: MOD. REPUESTOS REP01 | H42: 19.31 | I42: 0 | J42: 137.78
A43: 04.01.01.01.0005 | B43: DESC VTAS RPTOS TOYOTA CONTADO CON IVA | C43: N | D43: 46066.208 | E43: REPTO | F43: 371 | G43: MOD. REPUESTOS REP01 | H43: 44.3 | I43: 0 | J43: 182.08
A44: 04.01.01.01.0005 | B44: DESC VTAS RPTOS TOYOTA CONTADO CON IVA | C44: N | D44: 46071.208 | E44: REPTO | F44: 372 | G44: MOD. REPUESTOS REP01 | H44: 30.16 | I44: 0 | J44: 212.24
A45: 04.01.01.01.0005 | B45: DESC VTAS RPTOS TOYOTA CONTADO CON IVA | C45: N | E45: REPTO | H45: 0 | I45: 0 | J45: 212.24
A46: 04.01.01.01.0005 | B46: DESC VTAS RPTOS TOYOTA CONTADO CON IVA | C46: N | D46: 46072.208 | E46: REPTO | F46: 373 | G46: MOD. REPUESTOS REP01 | H46: 7.39 | I46: 0 | J46: 219.63
A47: 04.01.01.01.0005 | B47: DESC VTAS RPTOS TOYOTA CONTADO CON IVA | C47: N | D47: 46076.208 | E47: REPTO | F47: 376 | G47: MOD. REPUESTOS REP01 | H47: 20.45 | I47: 0 | J47: 240.08
A48: 04.01.01.01.0005 | B48: DESC VTAS RPTOS TOYOTA CONTADO CON IVA | C48: N | D48: 46077.208 | E48: REPTO | F48: 377 | G48: MOD. REPUESTOS REP01 | H48: 35.53 | I48: 0 | J48: 275.61
A49: 04.01.01.01.0005 | B49: DESC VTAS RPTOS TOYOTA CONTADO CON IVA | C49: N | D49: 46079.208 | E49: REPTO | F49: 379 | G49: MOD. REPUESTOS REP01 | H49: 3.6 | I49: 0 | J49: 279.21
A50: 04.01.01.01.0005 | B50: DESC VTAS RPTOS TOYOTA CONTADO CON IVA | C50: N | D50: 46081.208 | E50: REPTO | F50: 381 | G50: MOD. REPUESTOS REP01 | H50: 9.35 | I50: 0 | J50: 288.56
A51: 04.01.01.01.0007 | B51: DESC VTAS RPTOS TOYOTA CREDITO CON IVA | C51: N | D51: 46071.208 | E51: REPTO | F51: 372 | G51: MOD. REPUESTOS REP01 | H51: 44.3 | I51: 0 | J51: 44.3
A52: 04.01.01.01.0007 | B52: DESC VTAS RPTOS TOYOTA CREDITO CON IVA | C52: N | D52: 46078.208 | E52: REPTO | F52: 378 | G52: MOD. REPUESTOS REP01 | H52: 59.7 | I52: 0 | J52: 104
H53: =SUM(H42:H52) -> 274.09 | I53: =SUM(I42:I52) -> 44.3
A57: 04.01.01.01.0009 | B57: DEVOL VTAS RPTOS TOYOTA CONTADO CON IVA | C57: N | E57: REPTO | H57: 0 | I57: 0

Sheet REP PEUGT
A1: TOYOTASERVICIOS S.A. | N1: Página: | P1: 1 | Q1: de | S1: 1
A2: REPUESTOS | N2: Fecha: | P2: Thu Mar 12 2026 17:46:54 GMT-0500 (hora de Ecuador)
N3: KMOYOLEMA
A4: TIPO DOCUMENTO: F% TODOS LOS TIPOS DE FACTURA
A5: CLIENTE: % TODOS LOS CLIENTES | P5: MARGEN
F6: FECHA FINAL: 28/02/2026
A7: FECHA INICIAL: 01/02/2026
A9: AN | B9: BODEGA | C9: FECHA | E9: # DOC | F9: SERIE | G9: DESCRIPCION | H9: AUTORIZACION | I9: RUC | J9: N° Cliente | K9: CLIENTE | M9: CLIENTE PUBLICO | P9: ITEM | R9: SUBTOT | T9: DESC | V9: NETO | W9: SIN IVA | X9: CON IVA | Y9: ECOVALOR | Z9: VAL. IVA | AA9: OTR.CAR | AB9: TRANSP | AC9: INTERES | AD9: TOT FAC | AE9: ANTICIPO | AF9: SALDO | AG9: COSTO | AH9: UTILIDAD | AI9: VENTA | AJ9: COSTO | AK9: SERIE FISICO | AL9: ASIENTO | AM9: AGENCIA | AN9: FORMA PAGO
A11: NO | B11: PEUR | C11: 06/02/2026 | E11: 000000850 | F11: 002-505 | G11: FACTURA CONTADO | H11: 0602202601189171221500120025050000008505658032311 | I11: 18XXXXXXX9 | J11: 137782 | K11: 4$Yl9,=(<,atA4E0D4i|I<M8L< | M11: NO | P11: 1 | R11: 20 | T11: 0 | V11: 20 | W11: 0 | X11: 20 | Y11: 0 | Z11: 3 | AA11: 0 | AB11: 0 | AC11: 0 | AD11: 23 | AE11: 23 | AF11: 0 | AG11: 11.94 | AH11: 8.06 | AI11: 40.300003 | AJ11: 67.50419 | AK11: 11 | AL11: 403 | AM11: 06 | AN11: CONTADO
A12: NO | B12: PEUR | C12: 11/02/2026 | E12: 000000853 | F12: 002-505 | G12: FACTURA CONTADO | H12: 1102202601189171221500120025050000008535658032319 | I12: 18XXXXXXX6 | J12: 151990 | K12: 14mPoKe=9<uXwSmEAD}` [uMIL&h(c | M12: NO | P12: 1 | R12: 290.06 | T12: 20.48 | V12: 269.58 | W12: 0 | X12: 269.58 | Y12: 0 | Z12: 40.44 | AA12: 0 | AB12: 0 | AC12: 0 | AD12: 310.02 | AE12: 0 | AF12: 0 | AG12: 223.13111 | AH12: 46.448883 | AI12: 17.230093 | AJ12: 20.816856 | AK12: 11 | AL12: 405 | AM12: 06 | AN12: CONTADO
A13: NO | B13: PEUR | C13: 13/02/2026 | E13: 000000855 | F13: 002-505 | G13: FACTURA CONTADO | H13: 1302202601189171221500120025050000008555658032319 | I13: 08XXXXXXX7001 | J13: 152015 | K13: H^U5`,?@Pf]=h4GHXneEp<OP`vm | M13: NO | P13: 1 | R13: 5 | T13: 0 | V13: 5 | W13: 0 | X13: 5 | Y13: 0 | Z13: 0.75 | AA13: 0 | AB13: 0 | AC13: 0 | AD13: 5.75 | AE13: 5.75 | AF13: 0 | AG13: 2.59 | AH13: 2.41 | AI13: 48.2 | AJ13: 93.0502 | AK13: 11 | AL13: 407 | AM13: 06 | AN13: CONTADO
A14: NO | B14: PER4 | C14: 13/02/2026 | E14: 000000856 | F14: 002-505 | G14: FACTURA CONTADO | H14: 1302202601189171221500120025050000008565658032314 | I14: 11XXXXXXX2 | J14: 152022 | K14: (;[h%lTY0Ccp-t\a8Kkx5|di@Ss!= | M14: NO | P14: 1 | R14: 1294.56 | T14: 0 | V14: 1294.56 | W14: 0 | X14: 1294.56 | Y14: 0 | Z14: 194.18 | AA14: 0 | AB14: 0 | AC14: 0 | AD14: 1488.74 | AE14: 0 | AF14: 0 | AG14: 995.82 | AH14: 298.74005 | AI14: 23.07657 | AJ14: 29.999403 | AK14: 11 | AL14: 407 | AM14: 06 | AN14: CONTADO
A15: NO | B15: PEUR | C15: 19/02/2026 | E15: 000000858 | F15: 002-505 | G15: FACTURA CONTADO | H15: 1902202601189171221500120025050000008585658032312 | I15: 18XXXXXXX0 | J15: 152044 | K15: 3~, ]`av;'4(ehi~C/<0mpq'K7D8ux | M15: NO | P15: 2 | R15: 360.87 | T15: 0 | V15: 360.87 | W15: 0 | X15: 360.87 | Y15: 0 | Z15: 54.13 | AA15: 0 | AB15: 0 | AC15: 0 | AD15: 415 | AE15: 415 | AF15: 0 | AG15: 209.115 | AH15: 151.75499 | AI15: 42.052536 | AJ15: 72.57011 | AK15: 11 | AL15: 409 | AM15: 06 | AN15: CONTADO
A16: NO | B16: PEUR | C16: 24/02/2026 | E16: 000000860 | F16: 002-505 | G16: FACTURA CONTADO | H16: 2402202601189171221500120025050000008605658032314 | I16: 18XXXXXXX7 | J16: 141696 | K16: .DUAaOC]6L]IiWKe>TeQq_SmF\mYyg | M16: NO | P16: 1 | R16: 201.34 | T16: 0 | V16: 201.34 | W16: 0 | X16: 201.34 | Y16: 0 | Z16: 30.2 | AA16: 0 | AB16: 0 | AC16: 0 | AD16: 231.54 | AE16: 231.54 | AF16: 0 | AG16: 120.8 | AH16: 80.53999 | AI16: 40.001984 | AJ16: 66.67217 | AK16: 11 | AL16: 411 | AM16: 06 | AN16: CONTADO
A17: NO | B17: PEUR | C17: 26/02/2026 | E17: 000000862 | F17: 002-505 | G17: FACTURA CONTADO | H17: 2602202601189171221500120025050000008625658032314 | I17: 18XXXXXXX8001 | J17: 6284 | K17: K1q#<*8%S9y+D2@-[A"3L:H5cI*;TB | M17: NO | P17: 1 | R17: 10.43 | T17: 0 | V17: 10.43 | W17: 0 | X17: 10.43 | Y17: 0 | Z17: 1.56 | AA17: 0 | AB17: 0 | AC17: 0 | AD17: 11.99 | AE17: 0 | AF17: 0 | AG17: 7.9660886 | AH17: 2.4639115 | AI17: 23.623312 | AJ17: 30.930004 | AK17: 11 | AL17: 413 | AM17: 06 | AN17: CONTADO
A18: NO | B18: PEUR | C18: 26/02/2026 | E18: 000000863 | F18: 002-505 | G18: FACTURA CONTADO | H18: 2602202601189171221500120025050000008635658032311 | I18: 16XXXXXXX6 | J18: 128410 | K18: *NyNXU8(2V"V`]@0:^*^heH8Bf | M18: NO | P18: 1 | R18: 185.45 | T18: 18.55 | V18: 166.9 | W18: 0 | X18: 166.9 | Y18: 0 | Z18: 25.04 | AA18: 0 | AB18: 0 | AC18: 0 | AD18: 191.94 | AE18: 0 | AF18: 0 | AG18: 117.54 | AH18: 49.359993 | AI18: 29.574594 | AJ18: 41.99421 | AK18: 11 | AL18: 413 | AM18: 06 | AN18: CONTADO
A19: NO | B19: PER4 | C19: 27/02/2026 | E19: 000000864 | F19: 002-505 | G19: FACTURA CONTADO | H19: 2702202601189171221500120025050000008645658032311 | I19: 18XXXXXXX9 | J19: 129316 | K19: ']jU,'aN/er]4/iV7mze<7q^?u#mD? | M19: NO | P19: 2 | R19: 137.29 | T19: 0 | V19: 137.29 | W19: 0 | X19: 137.29 | Y19: 0 | Z19: 20.59 | AA19: 0 | AB19: 0 | AC19: 0 | AD19: 157.88 | AE19: 0 | AF19: 0 | AG19: 125.05 | AH19: 12.23999 | AI19: 8.915428 | AJ19: 9.788076 | AK19: 11 | AL19: 414 | AM19: 06 | AN19: CONTADO
A20: NO | B20: PER4 | C20: 10/02/2026 | E20: 000000851 | F20: 002-505 | G20: FACTURA CREDITO | H20: 1002202601189171221500120025050000008515658032313 | I20: 03XXXXXXX5001 | J20: 136649 | K20: o:!s.#@6wB){6+H> J1$>3PF(R | M20: NO | P20: 1 | R20: 331.14 | T20: 0 | V20: 331.14 | W20: 0 | X20: 331.14 | Y20: 0 | Z20: 49.67 | AA20: 0 | AB20: 0 | AC20: 0 | AD20: 380.81 | AE20: 0 | AF20: 0 | AG20: 206.96 | AH20: 124.18001 | AI20: 37.500755 | AJ20: 60.001934 | AK20: 11 | AL20: 404 | AM20: 06 | AN20: CREDITO
A21: NO | B21: PER4 | C21: 10/02/2026 | E21: 000000852 | F21: 002-505 | G21: FACTURA CREDITO | H21: 1002202601189171221500120025050000008525658032319 | I21: 18XXXXXXX4001 | J21: 53088 | K21: qVP{,xm.y^X$4!u6"f`,<)}>*n | M21: NO | P21: 3 | R21: 3033.28 | T21: 209.42 | V21: 2823.86 | W21: 0 | X21: 2823.86 | Y21: 0 | Z21: 423.58 | AA21: 0 | AB21: 0 | AC21: 0 | AD21: 3247.44 | AE21: 0 | AF21: 0 | AG21: 2373.3324 | AH21: 450.5276 | AI21: 15.954317 | AJ21: 18.98291 | AK21: 11 | AL21: 404 | AM21: 06 | AN21: CREDITO
A22: NO | B22: PER4 | C22: 12/02/2026 | E22: 000000854 | F22: 002-505 | G22: FACTURA CREDITO | H22: 1202202601189171221500120025050000008545658032319 | I22: 01XXXXXXX6001 | J22: 130044 | K22: &(#d#$^f.0+l+,fn683t34nv>@;|;< | M22: NO | P22: 2 | R22: 540.46 | T22: 0 | V22: 540.46 | W22: 0 | X22: 540.46 | Y22: 0 | Z22: 81.07 | AA22: 0 | AB22: 0 | AC22: 0 | AD22: 621.53 | AE22: 0 | AF22: 0 | AG22: 429.21895 | AH22: 111.24106 | AI22: 20.58266 | AJ22: 25.91709 | AK22: 11 | AL22: 406 | AM22: 06 | AN22: CREDITO
... A28: NO | B28: PER4 | C28: 27/02/2026 | E28: 000000867 | F28: 002-505 | G28: FACTURA CREDITO | H28: 2702202601189171221500120025050000008675658032316 | I28: 18XXXXXXX8001 | J28: 906 | K28: wC>x51o$ KF!=9w,(SN)EA 40[V1MI | M28: NO | P28: 3 | R28: 938.85 | T28: 0 | V28: 938.85 | W28: 0 | X28: 938.85 | Y28: 0 | Z28: 140.83 | AA28: 0 | AB28: 0 | AC28: 0 | AD28: 1079.68 | AE28: 0 | AF28: 0 | AG28: 722.19 | AH28: 216.65997 | AI28: 23.077166 | AJ28: 30.000412 | AK28: 11 | AL28: 414 | AM28: 06 | AN28: CREDITO
L30: TOTAL GENERAL: | P30: 15666.44 | R30: 248.45 | T30: 15417.988 | V30: 0 | W30: 15417.99 | X30: 2312.7 | Y30: 0 | AA30: 0 | AB30: 17730.69 | AC30: 0 | AD30: 0 | AE30: 675.29 | AF30: 11986.423 | AG30: 11986.423 | AH30: 3431.568 | AI30: 22.256895 | AJ30: 28.628769
N31: MAYOR | P31: =+'MY REP PEUG'!I19 | R31: =+'MY REP PEUG'!H25 | Y31: =+X30-'NC REP PEUG'!AD9:AE9 | Z31: =X30

Sheet NC REP PEUG
B1: TOYOTASERVICIOS S.A. | F1: DEVOLUCIÓN DE VENTAS
B2: REPUESTOS | AC2: Fecha: | AE2: 46085.746
B3: FECHA INICIAL: 01/02/2026
AC4: RepLibroDevolucionesGeneralCB
A5: FECHA FINAL: 28/02/2026
A7: ANULADA | C7: BODEGA | D7: FECHA NC | E7: CODIGO | G7: AGENCIA | H7: SERIE | I7: N/C No. | J7: DEV. A FAC. | K7: DESCRIPCION | L7: AUTORIZACION | N7: FECHA FACT | O7: TOt FACT | P7: CEDULA | R7: COD CLI | T7: CLIENTE | U7: CLIENTE PUBLICO | V7: ITEM | W7: SUBTOT | X7: DESC | Y7: NETO | Z7: SIN IVA | AA7: CON IVA | AB7: ECOVALOR | AD7: VAL. IVA | AF7: OTR.CAR | AG7: INTERES | AH7: TRANSPORTE | AJ7: TOT. NC | AK7: ANTICIPO | AL7: S/NOTA CR | AM7: COSTO | AN7: UTILIDAD | AO7: ASIENTO | AP7: FORMA PAGO
AF8: 0 | AG8: 0 | AH8: 0 | AJ8: 23 | AK8: 0 | AM8: 11.35 | AN8: 11.65 | AO8: 402 | AP8: CONTADO
M9: TOTAL GENERAL: | V9: 0 | W9: 0 | X9: 0 | Y9: 0 | Z9: 0 | AA9: 0 | AB9: 0 | AD9: 0 | AG9: 0 | AH9: 0 | AJ9: 23 | AK9: 0 | AM9: 11.35 | AN9: 11.65
V10: MAYOR | W10: =+'MY REP PEUG'!H28 -> 20

Sheet MY REP PEUG
A1: CUENTA | B1: NOMBRE | C1: N/M | D1: FECHA | E1: TIPO | F1: NO. | G1: DETALLE | H1: DEBITO | I1: CREDITO | J1: SALDO
A2: 04.01.01.03.0001 | B2: VTAS RPTOS PEUGEOT - CONTADO CON IVA | C2: N | D2: 46059.208 | E2: REPTO | F2: 403 | G2: MOD. REPUESTOS REP06 | H2: 0 | I2: 20 | J2: -1821.32
A3: 04.01.01.03.0001 | B3: VTAS RPTOS PEUGEOT - CONTADO CON IVA | C3: N | D3: 46064.208 | E3: REPTO | F3: 405 | G3: MOD. REPUESTOS REP06 | H3: 0 | I3: 290.06 | J3: -2111.38
A4: 04.01.01.03.0001 | B4: VTAS RPTOS PEUGEOT - CONTADO CON IVA | C4: N | D4: 46066.208 | E4: REPTO | F4: 407 | G4: MOD. REPUESTOS REP06 | H4: 0 | I4: 1299.56 | J4: -3410.94
A5: 04.01.01.03.0001 | B5: VTAS RPTOS PEUGEOT - CONTADO CON IVA | C5: N | D5: 46072.208 | E5: REPTO | F5: 409 | G5: MOD. REPUESTOS REP06 | H5: 0 | I5: 360.87 | J5: -3771.81
A6: 04.01.01.03.0001 | B6: VTAS RPTOS PEUGEOT - CONTADO CON IVA | C6: N | D6: 46077.208 | E6: REPTO | F6: 411 | G6: MOD. REPUESTOS REP06 | H6: 0 | I6: 201.34 | J6: -3973.15
A7: 04.01.01.03.0001 | B7: VTAS RPTOS PEUGEOT - CONTADO CON IVA | C7: N | D7: 46079.208 | E7: REPTO | F7: 413 | G7: MOD. REPUESTOS REP06 | H7: 0 | I7: 195.88 | J7: -4169.03
A8: 04.01.01.03.0001 | B8: VTAS RPTOS PEUGEOT - CONTADO CON IVA | C8: N | D8: 46080.208 | E8: REPTO | F8: 414 | G8: MOD. REPUESTOS REP06 | H8: 0 | I8: 137.29 | J8: -4306.32
A9: 04.01.01.03.0003 | B9: VTAS RPTOS PEUGEOT - CREDITO CON IVA | C9: N | D9: 46063.208 | E9: REPTO | F9: 404 | G9: MOD. REPUESTOS REP06 | H9: 0 | I9: 1486.1 | J9: -1576.62
A10: 04.01.01.03.0003 | B10: VTAS RPTOS PEUGEOT - CREDITO CON IVA | C10: N | D10: 46063.208 | E10: REPTO | F10: 404 | G10: MOD. REPUESTOS REP06 | H10: 0 | I10: 1878.32 | J10: -3454.94
A11: 04.01.01.03.0003 | B11: VTAS RPTOS PEUGEOT - CREDITO CON IVA | C11: N | D11: 46065.208 | E11: REPTO | F11: 406 | G11: MOD. REPUESTOS REP06 | H11: 0 | I11: 286.96 | J11: -3741.9
A12: 04.01.01.03.0003 | B12: VTAS RPTOS PEUGEOT - CREDITO CON IVA | C12: N | D12: 46065.208 | E12: REPTO | F12: 406 | G12: MOD. REPUESTOS REP06 | H12: 0 | I12: 253.5 | J12: -3995.4
A13: 04.01.01.03.0003 | B13: VTAS RPTOS PEUGEOT - CREDITO CON IVA | C13: N | D13: 46071.208 | E13: REPTO | F13: 408 | G13: MOD. REPUESTOS REP06 | H13: 0 | I13: 242.37 | J13: -4237.77
... A18: 04.01.01.03.0003 | B18: VTAS RPTOS PEUGEOT - CREDITO CON IVA | C18: N | D18: 46080.208 | E18: REPTO | F18: 414 | G18: MOD. REPUESTOS REP06 | H18: 0 | I18: 93.26 | J18: -13251.96
H19: =SUM(H2:H18) -> 0 | I19: =SUM(I2:I18) -> 15666.44
A21: 04.01.01.03.0005 | B21: DESC VTAS RPTOS PEUGEOT CONTADO CON IVA | C21: N | D21: 46064.208 | E21: REPTO | F21: 405 | G21: MOD. REPUESTOS REP06 | H21: 20.48 | I21: 0 | J21: 124.31
A22: 04.01.01.03.0005 | B22: DESC VTAS RPTOS PEUGEOT CONTADO CON IVA | C22: N | D22: 46079.208 | E22: REPTO | F22: 413 | G22: MOD. REPUESTOS REP06 | H22: 18.55 | I22: 0 | J22: 142.86
A23: 04.01.01.03.0007 | B23: DESC VTAS RPTOS PEUGEOT CREDITO CON IVA | C23: N | D23: 46063.208 | E23: REPTO | F23: 404 | G23: MOD. REPUESTOS REP06 | H23: 93.92 | I23: 0 | J23: 93.92
A24: 04.01.01.03.0007 | B24: DESC VTAS RPTOS PEUGEOT CREDITO CON IVA | C24: N | D24: 46063.208 | E24: REPTO | F24: 404 | G24: MOD. REPUESTOS REP06 | H24: 115.5 | I24: 0 | J24: 209.42
H25: =SUM(H21:H24) -> 248.45
A28: 04.01.01.03.0009 | B28: DEVOL VTAS RPTOS PEUGEOT CONTADO CON IVA | C28: N | E28: REPTO | H28: 0 | I28: 0

Sheet REP CHGN
A1: TOYOTASERVICIOS S.A. | N1: Página: | P1: 1 | Q1: de | S1: 1
A2: REPUESTOS | N2: Fecha: | P2: Thu Mar 12 2026 17:46:58 GMT-0500 (hora de Ecuador)
N3: KMOYOLEMA
A4: TIPO DOCUMENTO: F% TODOS LOS TIPOS DE FACTURA
A5: CLIENTE: % TODOS LOS CLIENTES | P5: MARGEN
F6: FECHA FINAL: 28/02/2026
A7: FECHA INICIAL: 01/02/2026
A9: AN | B9: BODEGA | C9: FECHA | E9: # DOC | F9: SERIE | G9: DESCRIPCION | H9: AUTORIZACION | I9: RUC | J9: N° Cliente | K9: CLIENTE | M9: CLIENTE PUBLICO | P9: ITEM | R9: SUBTOT | T9: DESC | V9: NETO | W9: SIN IVA | X9: CON IVA | Y9: ECOVALOR | Z9: VAL. IVA | AA9: OTR.CAR | AB9: TRANSP | AC9: INTERES | AD9: TOT FAC | AE9: ANTICIPO | AF9: SALDO | AG9: COSTO | AH9: UTILIDAD | AI9: VENTA | AJ9: COSTO | AK9: SERIE FISICO | AL9: ASIENTO | AM9: AGENCIA | AN9: FORMA PAGO
A11: NO | B11: CHAR | C11: 03/02/2026 | E11: 000000677 | F11: 005-505 | G11: FACTURA CONTADO | H11: 0302202601189171221500120055050000006775658032314 | I11: 02XXXXXXX5 | J11: 110121 | K11: HkW];+64Ps_eC3><X{gmK;FD`$ouSC | M11: NO | P11: 1 | R11: 21 | T11: 1.05 | V11: 19.95 | W11: 0 | X11: 19.95 | Y11: 0 | Z11: 2.99 | AA11: 0 | AB11: 0 | AC11: 0 | AD11: 22.94 | AE11: 0 | AF11: 0 | AG11: 10.665 | AH11: 9.285001 | AI11: 46.54136 | AJ11: 87.060486 | AK11: 23 | AL11: 415 | AM11: 05 | AN11: CONTADO
A12: NO | B12: CHAR | C12: 03/02/2026 | E12: 000000678 | F12: 005-505 | G12: FACTURA CONTADO | H12: 0302202601189171221500120055050000006785658032311 | I12: 16XXXXXXX2 | J12: 151382 | K12: qI6zBBeByQ>#JJmJ"YF+RRuR* | M12: NO | P12: 1 | R12: 856.52 | T12: 0 | V12: 856.52 | W12: 0 | X12: 856.52 | Y12: 0 | Z12: 128.48 | AA12: 0 | AB12: 0 | AC12: 0 | AD12: 985 | AE12: 985 | AF12: 0 | AG12: 503.71 | AH12: 352.81003 | AI12: 41.1911 | AJ12: 70.0423 | AK12: 23 | AL12: 415 | AM12: 05 | AN12: CONTADO
A13: NO | B13: CHAR | C13: 03/02/2026 | E13: 000000679 | F13: 005-505 | G13: FACTURA CONTADO | H13: 0302202601189171221500120055050000006795658032315 | I13: 05XXXXXXX6001 | J13: 151304 | K13: B*[yk=ccJ2c"sEkkR:k*{MssZBs2$U | M13: NO | P13: 1 | R13: 230.43 | T13: 0 | V13: 230.43 | W13: 0 | X13: 230.43 | Y13: 0 | Z13: 34.56 | AA13: 0 | AB13: 0 | AC13: 0 | AD13: 264.99 | AE13: 264.99 | AF13: 0 | AG13: 139.95 | AH13: 90.479996 | AI13: 39.26572 | AJ13: 64.651665 | AK13: 23 | AL13: 415 | AM13: 05 | AN13: CONTADO
A14: NO | B14: CHAR | C14: 03/02/2026 | E14: 000000680 | F14: 005-505 | G14: FACTURA CONTADO | H14: 0302202601189171221500120055050000006805658032310 | I14: 05XXXXXXX2 | J14: 118812 | K14: /L,OTNIO7T4W\VQW?\<_d^Y_GdDg | M14: NO | P14: 1 | R14: 25.6 | T14: 0 | V14: 25.6 | W14: 0 | X14: 25.6 | Y14: 0 | Z14: 3.84 | AA14: 0 | AB14: 0 | AC14: 0 | AD14: 29.44 | AE14: 29.44 | AF14: 0 | AG14: 15.136346 | AH14: 10.463654 | AI14: 40.873646 | AJ14: 69.12932 | AK14: 23 | AL14: 415 | AM14: 05 | AN14: CONTADO
A15: NO | B15: CHAR | C15: 05/02/2026 | E15: 000000681 | F15: 005-505 | G15: FACTURA CONTADO | H15: 0502202601189171221500120055050000006815658032315 | I15: 14XXXXXXX3001 | J15: 132886 | K15: ,;Ff`l7E4CNnht?M<KVvp|GUDS^ | M15: NO | P15: 4 | R15: 297.32 | T15: 14.88 | V15: 282.44 | W15: 0 | X15: 282.44 | Y15: 0 | Z15: 42.37 | AA15: 0 | AB15: 0 | AC15: 0 | AD15: 324.81 | AE15: 324.81 | AF15: 0 | AG15: 185.38097 | AH15: 97.05904 | AI15: 34.36448 | AJ15: 52.35653 | AK15: 23 | AL15: 416 | AM15: 05 | AN15: CONTADO
A16: NO | B16: CHAR | C16: 06/02/2026 | E16: 000000682 | F16: 005-505 | G16: FACTURA CONTADO | H16: 0602202601189171221500120055050000006825658032315 | I16: 17XXXXXXX0 | J16: 119817 | K16: 7$J1]?eX?,R9eGm`G4ZAmOuhO<bI | M16: NO | P16: 2 | R16: 148.52 | T16: 0 | V16: 148.52 | W16: 0 | X16: 148.52 | Y16: 0 | Z16: 22.28 | AA16: 0 | AB16: 0 | AC16: 0 | AD16: 170.8 | AE16: 0 | AF16: 0 | AG16: 90.299762 | AH16: 58.220245 | AI16: 39.20027 | AJ16: 64.47442 | AK16: 23 | AL16: 417 | AM16: 05 | AN16: CONTADO
A17: NO | B17: CHAR | C17: 06/02/2026 | E17: 000000683 | F17: 005-505 | G17: FACTURA CONTADO | H17: 0602202601189171221500120055050000006835658032310 | I17: 05XXXXXXX7 | J17: 137438 | K17: [5L(V[dFc=T0^clNkE\8fktVsMd@ns | M17: NO | P17: 1 | R17: 40.24 | T17: 0.01 | V17: 40.23 | W17: 0 | X17: 40.23 | Y17: 0 | Z17: 6.03 | AA17: 0 | AB17: 0 | AC17: 0 | AD17: 46.26 | AE17: 46.26 | AF17: 0 | AG17: 23.74 | AH17: 16.49 | AI17: 40.98931 | AJ17: 69.46083 | AK17: 23 | AL17: 417 | AM17: 05 | AN17: CONTADO
A18: NO | B18: CHAR | C18: 11/02/2026 | E18: 000000685 | F18: 005-505 | G18: FACTURA CONTADO | H18: 1102202601189171221500120055050000006855658032312 | I18: 17XXXXXXX3001 | J18: 142594 | K18: 68~]>/BW>@'eF7J_FH/mN?RgNP7uVG | M18: NO | P18: 2 | R18: 71.48 | T18: 0 | V18: 71.48 | W18: 0 | X18: 71.48 | Y18: 0 | Z18: 10.72 | AA18: 0 | AB18: 0 | AC18: 0 | AD18: 82.2 | AE18: 82.2 | AF18: 0 | AG18: 38.5 | AH18: 32.980003 | AI18: 46.138783 | AJ18: 85.662346 | AK18: 23 | AL18: 418 | AM18: 05 | AN18: CONTADO
A19: NO | B19: CHAR | C19: 18/02/2026 | E19: 000000686 | F19: 005-505 | G19: FACTURA CONTADO | H19: 1802202601189171221500120055050000006865658032311 | I19: 18XXXXXXX1001 | J19: 152057 | K19: Pd1F%oNgXl9N-wVo`tAV5 ^wh|I^=( | M19: NO | P19: 1 | R19: 14.35 | T19: 0 | V19: 14.35 | W19: 0 | X19: 14.35 | Y19: 0 | Z19: 2.15 | AA19: 0 | AB19: 0 | AC19: 0 | AD19: 16.5 | AE19: 0 | AF19: 0 | AG19: 4.6966667 | AH19: 9.653334 | AI19: 67.27062 | AJ19: 205.53584 | AK19: 23 | AL19: 419 | AM19: 05 | AN19: CONTADO
A20: NO | B20: CHAR | C20: 11/02/2026 | E20: 000000684 | F20: 005-505 | G20: FACTURA CREDITO | H20: 1102202601189171221500120055050000006845658032317 | I20: 10XXXXXXX3001 | J20: 60115 | K20: LrC#QGTsTzK+YO\{\#S3aWd$d+[;i_ | M20: NO | P20: 1 | R20: 80 | T20: 0 | V20: 80 | W20: 0 | X20: 80 | Y20: 0 | Z20: 12 | AA20: 0 | AB20: 0 | AC20: 0 | AD20: 92 | AE20: 0 | AF20: 0 | AG20: 34.81 | AH20: 45.19 | AI20: 56.4875 | AJ20: 129.81902 | AK20: 23 | AL20: 418 | AM20: 05 | AN20: CREDITO
L22: TOTAL GENERAL: | P22: 1785.46 | R22: 15.94 | T22: 1769.5199 | V22: 0 | W22: 1769.52 | X22: 265.42 | Y22: 0 | AA22: 0 | AB22: 2034.94 | AC22: 0 | AD22: 0 | AE22: 1732.7 | AF22: 1046.8888 | AG22: 1046.8888 | AH22: 722.6313 | AI22: 40.837692 | AJ22: 69.02654
N23: MAYOR | P23: =+'MY REP CHGN'!J8 | S23: =+'MY REP CHGN'!I15

Sheet MY REP CHGN
A1: CUENTA | B1: NOMBRE | D1: FECHA | E1: TIPO | F1: NO. | G1: EST. | H1: REFER | I1: DETALLE | J1: DEBITO | K1: CREDITO | L1: SALDO
A2: 04.01.01.02.0001 | B2: VTAS RPTOS CHANGAN - CONTADO CON IVA | C2: N | D2: 46056.208 | E2: REPTO | F2: 415 | H2: MOD. REPUESTOS REP05 | I2: 0 | J2: 1133.55 | K2: -1606.54
A3: 04.01.01.02.0001 | B3: VTAS RPTOS CHANGAN - CONTADO CON IVA | C3: N | D3: 46058.208 | E3: REPTO | F3: 416 | H3: MOD. REPUESTOS REP05 | I3: 0 | J3: 297.32 | K3: -1903.86
A4: 04.01.01.02.0001 | B4: VTAS RPTOS CHANGAN - CONTADO CON IVA | C4: N | D4: 46059.208 | E4: REPTO | F4: 417 | H4: MOD. REPUESTOS REP05 | I4: 0 | J4: 188.76 | K4: -2092.62
A5: 04.01.01.02.0001 | B5: VTAS RPTOS CHANGAN - CONTADO CON IVA | C5: N | D5: 46064.208 | E5: REPTO | F5: 418 | H5: MOD. REPUESTOS REP05 | I5: 0 | J5: 71.48 | K5: -2164.1
A6: 04.01.01.02.0001 | B6: VTAS RPTOS CHANGAN - CONTADO CON IVA | C6: N | D6: 46071.208 | E6: REPTO | F6: 419 | H6: MOD. REPUESTOS REP05 | I6: 0 | J6: 14.35 | K6: -2178.45
A7: 04.01.01.02.0003 | B7: VTAS RPTOS CHANGAN - CREDITO CON IVA | C7: N | D7: 46064.208 | E7: REPTO | F7: 418 | H7: MOD. REPUESTOS REP05 | I7: 0 | J7: 80 | K7: -1922.46
J8: =SUM(J2:J7) -> 1785.46
A12: 04.01.01.02.0005 | B12: DESC VTAS RPTOS CHANGAN CONTADO CON IVA | C12: N | D12: 46056.208 | E12: REPTO | F12: 415 | H12: MOD. REPUESTOS REP05 | I12: 1.05 | J12: 0 | K12: 2.6
A13: 04.01.01.02.0005 | B13: DESC VTAS RPTOS CHANGAN CONTADO CON IVA | C13: N | D13: 46058.208 | E13: REPTO | F13: 416 | H13: MOD. REPUESTOS REP05 | I13: 14.88 | J13: 0 | K13: 17.48
A14: 04.01.01.02.0005 | B14: DESC VTAS RPTOS CHANGAN CONTADO CON IVA | C14: N | D14: 46059.208 | E14: REPTO | F14: 417 | H14: MOD. REPUESTOS REP05 | I14: 0.01 | J14: 0 | K14: 17.49
I15: =SUM(I12:I14) -> 15.94

Sheet REP SZK
A1: TOYOTASERVICIOS S.A. | N1: Página: | P1: 1 | Q1: de | S1: 2
A2: REPUESTOS | N2: Fecha: | P2: Thu Mar 12 2026 17:47:02 GMT-0500 (hora de Ecuador)
N3: KMOYOLEMA
A4: TIPO DOCUMENTO: F% TODOS LOS TIPOS DE FACTURA
A5: CLIENTE: % TODOS LOS CLIENTES | P5: MARGEN
F6: FECHA FINAL: 28/02/2026
A7: FECHA INICIAL: 01/02/2026
A9: AN | B9: BODEGA | C9: FECHA | E9: # DOC | F9: SERIE | G9: DESCRIPCION | H9: AUTORIZACION | I9: RUC | J9: N° Cliente | K9: CLIENTE | M9: CLIENTE PUBLICO | P9: ITEM | R9: SUBTOT | T9: DESC | V9: NETO | W9: SIN IVA | X9: CON IVA | Y9: ECOVALOR | Z9: VAL. IVA | AA9: OTR.CAR | AB9: TRANSP | AC9: INTERES | AD9: TOT FAC | AE9: ANTICIPO | AF9: SALDO | AG9: COSTO | AH9: UTILIDAD | AI9: VENTA | AJ9: COSTO | AK9: SERIE FISICO | AL9: ASIENTO | AM9: AGENCIA | AN9: FORMA PAGO
A11: NO | B11: SUZR | C11: 02/02/2026 | E11: 000001289 | F11: 006-505 | G11: FACTURA CONTADO | H11: 0202202601189171221500120065050000012895658032314 | I11: 17XXXXXXX1 | J11: 151799 | K11: $TI_?g`c,\QgGohk4dYoOwps<lawW | M11: NO | P11: 2 | R11: 27.86 | T11: 0 | V11: 27.86 | W11: 0 | X11: 27.86 | Y11: 0 | Z11: 4.18 | AA11: 0 | AB11: 0 | AC11: 0 | AD11: 32.04 | AE11: 0 | AF11: 0 | AG11: 18.387447 | AH11: 9.472553 | AI11: 34.00055 | AJ11: 51.516415 | AK11: 32 | AL11: 382 | AM11: 07 | AN11: CONTADO
A12: NO | B12: SUZR | C12: 03/02/2026 | E12: 000001290 | F12: 006-505 | G12: FACTURA CONTADO | H12: 0302202601189171221500120065050000012905658032314 | I12: 18XXXXXXX7 | J12: 151797 | K12: s,5dIc['{4=lQkc/$<EtYsk7,DM | M12: NO | P12: 1 | R12: 95.92 | T12: 9.59 | V12: 86.33 | W12: 0 | X12: 86.33 | Y12: 0 | Z12: 12.95 | AA12: 0 | AB12: 0 | AC12: 0 | AD12: 99.28 | AE12: 0 | AF12: 0 | AG12: 50.587656 | AH12: 35.742344 | AI12: 41.401997 | AJ12: 70.65428 | AK12: 32 | AL12: 383 | AM12: 07 | AN12: CONTADO
A13: NO | B13: SUZR | C13: 03/02/2026 | E13: 000001291 | F13: 006-505 | G13: FACTURA CONTADO | H13: 0302202601189171221500120065050000012915658032311 | I13: 17XXXXXXX2 | J13: 151449 | K13: v0a'f&/:~8i/n.7B'@q7v6?J | M13: NO | P13: 1 | R13: 75.61 | T13: 0 | V13: 75.61 | W13: 0 | X13: 75.61 | Y13: 0 | Z13: 11.34 | AA13: 0 | AB13: 0 | AC13: 0 | AD13: 86.95 | AE13: 86.95 | AF13: 0 | AG13: 49.9 | AH13: 25.71 | AI13: 34.003437 | AJ13: 51.52304 | AK13: 32 | AL13: 383 | AM13: 07 | AN13: CONTADO
A14: NO | B14: SUZR | C14: 03/02/2026 | E14: 000001292 | F14: 006-505 | G14: FACTURA CONTADO | H14: 0302202601189171221500120065050000012925658032315 | I14: 05XXXXXXX0001 | J14: 134734 | K14: G%D;eZZ9O-LCmbbAW5TKujjI_=\S}r | M14: NO | P14: 1 | R14: 38 | T14: 1.9 | V14: 36.1 | W14: 0 | X14: 36.1 | Y14: 0 | Z14: 5.42 | AA14: 0 | AB14: 0 | AC14: 0 | AD14: 41.52 | AE14: 41.52 | AF14: 0 | AG14: 20 | AH14: 16.099998 | AI14: 44.598335 | AJ14: 80.49999 | AK14: 32 | AL14: 383 | AM14: 07 | AN14: CONTADO
A15: NO | B15: SUZR | C15: 03/02/2026 | E15: 000001293 | F15: 006-505 | G15: FACTURA CONTADO | H15: 0302202601189171221500120065050000012935658032310 | I15: 10XXXXXXX3001 | J15: 148977 | K15: IC }eb*wQK(&mj2 YS0.ur:(a[8 | M15: NO | P15: 2 | R15: 8.69 | T15: 0 | V15: 8.69 | W15: 0 | X15: 8.69 | Y15: 0 | Z15: 1.3 | AA15: 0 | AB15: 0 | AC15: 0 | AD15: 9.99 | AE15: 9.99 | AF15: 0 | AG15: 5.0288495 | AH15: 3.66115 | AI15: 42.13061 | AJ15: 72.80293 | AK15: 32 | AL15: 383 | AM15: 07 | AN15: CONTADO
A16: NO | B16: SUZR | C16: 03/02/2026 | E16: 000001294 | F16: 006-505 | G16: FACTURA CONTADO | H16: 0302202601189171221500120065050000012945658032316 | I16: 17XXXXXXX3 | J16: 151667 | K16: !(&.6. @)0.6>6(H186>F>0P9@>FNF | M16: NO | P16: 1 | R16: 30.33 | T16: 0 | V16: 30.33 | W16: 0 | X16: 30.33 | Y16: 0 | Z16: 4.55 | AA16: 0 | AB16: 0 | AC16: 0 | AD16: 34.88 | AE16: 34.88 | AF16: 0 | AG16: 20.02 | AH16: 10.309999 | AI16: 33.992744 | AJ16: 51.498497 | AK16: 32 | AL16: 383 | AM16: 07 | AN16: CONTADO
A17: NO | B17: SUZR | C17: 03/02/2026 | E17: 000001295 | F17: 006-505 | G17: FACTURA CONTADO | H17: 0302202601189171221500120065050000012955658032311 | I17: 18XXXXXXX5 | J17: 127159 | K17: jhCcN6&UrpKkV>.]zxSs^F6e#![{ | M17: NO | P17: 1 | R17: 139.83 | T17: 0 | V17: 139.83 | W17: 0 | X17: 139.83 | Y17: 0 | Z17: 20.97 | AA17: 0 | AB17: 0 | AC17: 0 | AD17: 160.8 | AE17: 160.8 | AF17: 0 | AG17: 92.29 | AH17: 47.54 | AI17: 33.99843 | AJ17: 51.51154 | AK17: 32 | AL17: 383 | AM17: 07 | AN17: CONTADO
A18: NO | B18: SZRR | C18: 04/02/2026 | E18: 000000247 | F18: 007-505 | G18: FACTURA CONTADO | H18: 0402202601189171221500120075050000002475658032311 | I18: 06XXXXXXX0 | J18: 151829 | K18: WBsS|H;s_J{[%PC{gR$c-XK$oZ, | M18: NO | P18: 1 | R18: 12.26 | T18: 0 | V18: 12.26 | W18: 0 | X18: 12.26 | Y18: 0 | Z18: 1.84 | AA18: 0 | AB18: 0 | AC18: 0 | AD18: 14.1 | AE18: 0 | AF18: 0 | AG18: 8.08 | AH18: 4.1800003 | AI18: 34.09462 | AJ18: 51.732677 | AK18: 32 | AL18: 384 | AM18: 08 | AN18: CONTADO
A19: NO | B19: SZRR | C19: 04/02/2026 | E19: 000000248 | F19: 007-505 | G19: FACTURA CONTADO | H19: 0402202601189171221500120075050000002485658032317 | I19: 06XXXXXXX3001 | J19: 151865 | K19: &;?@TF/D.CGH\N7L6KOPdV?T>SWXl^ | M19: NO | P19: 1 | R19: 13.04 | T19: 0 | V19: 13.04 | W19: 0 | X19: 13.04 | Y19: 0 | Z19: 1.96 | AA19: 0 | AB19: 0 | AC19: 0 | AD19: 15 | AE19: 0 | AF19: 0 | AG19: 8.11 | AH19: 4.9300003 | AI19: 37.80675 | AJ19: 60.789154 | AK19: 32 | AL19: 384 | AM19: 08 | AN19: CONTADO
A20: NO | B20: SUZR | C20: 04/02/2026 | E20: 000001296 | F20: 006-505 | G20: FACTURA CONTADO | H20: 0402202601189171221500120065050000012965658032311 | I20: 16XXXXXXX0 | J20: 151732 | K20: b!y|((__j)"%00ggr1*-88ooz92 | M20: NO | P20: 1 | R20: 82.5 | T20: 0 | V20: 82.5 | W20: 0 | X20: 82.5 | Y20: 0 | Z20: 12.38 | AA20: 0 | AB20: 0 | AC20: 0 | AD20: 94.88 | AE20: 94.88 | AF20: 0 | AG20: 56 | AH20: 26.5 | AI20: 32.121212 | AJ20: 47.32143 | AK20: 32 | AL20: 384 | AM20: 07 | AN20: CONTADO
A21: NO | B21: SUZR | C21: 04/02/2026 | E21: 000001297 | F21: 006-505 | G21: FACTURA CONTADO | H21: 0402202601189171221500120065050000012975658032317 | I21: 05XXXXXXX7 | J21: 138108 | K21: I}h15YHpQ&p9=aPxY.xAEiX!a6!I | M21: NO | P21: 21 | R21: 2782.03 | T21: 278.21 | V21: 2503.82 | W21: 0 | X21: 2503.82 | Y21: 0 | Z21: 375.57 | AA21: 0 | AB21: 0 | AC21: 0 | AD21: 2879.39 | AE21: 2879.39 | AF21: 0 | AG21: 1841.9418 | AH21: 661.8783 | AI21: 26.434738 | AJ21: 35.933723 | AK21: 32 | AL21: 384 | AM21: 07 | AN21: CONTADO
A22: NO | B22: SUZR | C22: 04/02/2026 | E22: 000001298 | F22: 006-505 | G22: FACTURA CONTADO | H22: 0402202601189171221500120065050000012985658032312 | I22: 22XXXXXXX4001 | J22: 147121 | K22: h|Z>*Cqxp%bF2Ky!x-jN:S")!5rVB | M22: NO | P22: 1 | R22: 253.17 | T22: 0 | V22: 253.17 | W22: 0 | X22: 253.17 | Y22: 0 | Z22: 37.98 | AA22: 0 | AB22: 0 | AC22: 0 | AD22: 291.15 | AE22: 291.15 | AF22: 0 | AG22: 157.9 | AH22: 95.270004 | AI22: 37.630844 | AJ22: 60.33566 | AK22: 32 | AL22: 384 | AM22: 07 | AN22: CONTADO
... A48: NO | B48: SUZR | C48: 26/02/2026 | E48: 000001322 | F48: 006-505 | G48: FACTURA CONTADO | H48: 2602202601189171221500120065050000013225658032318 | I48: 05XXXXXXX6 | J48: 146068 | K48: a#>Y?*?di+FaG2Glq3N | M48: NO | P48: 2 | R48: 49.24 | T48: 0 | V48: 49.24 | W48: 0 | X48: 49.24 | Y48: 0 | Z48: 7.39 | AA48: 0 | AB48: 0 | AC48: 0 | AD48: 56.63 | AE48: 56.63 | AF48: 0 | AG48: 32.521218 | AH48: 16.718784 | AI48: 33.953663 | AJ48: 51.40885 | AK48: 32 | AL48: 399 | AM48: 07 | AN48: CONTADO
A49: AN | B49: BODEGA | C49: FECHA | E49: # DOC | F49: SERIE | G49: DESCRIPCION | H49: AUTORIZACION | I49: RUC | J49: N° Cliente | K49: CLIENTE | M49: CLIENTE PUBLICO | P49: ITEM | R49: SUBTOT | T49: DESC | V49: NETO | W49: SIN IVA | X49: CON IVA | Y49: ECOVALOR | Z49: VAL. IVA | AA49: OTR.CAR | AB49: TRANSP | AC49: INTERES | AD49: TOT FAC | AE49: ANTICIPO | AF49: SALDO | AG49: COSTO | AH49: UTILIDAD | AI49: VENTA | AJ49: COSTO | AK49: SERIE FISICO | AL49: ASIENTO | AM49: AGENCIA | AN49: FORMA PAGO
A51: NO | B51: SUZR | C51: 28/02/2026 | E51: 000001324 | F51: 006-505 | G51: FACTURA CONTADO | H51: 2802202601189171221500120065050000013245658032318 | I51: 18XXXXXXX4 | J51: 135925 | K51: 9p`J@34DAxhRH;<LI!pZPCDTQ)xbX | M51: NO | P51: 3 | R51: 52.46 | T51: 0 | V51: 52.46 | W51: 0 | X51: 52.46 | Y51: 0 | Z51: 7.87 | AA51: 0 | AB51: 0 | AC51: 0 | AD51: 60.33 | AE51: 0 | AF51: 0 | AG51: 34.627167 | AH51: 17.832832 | AI51: 33.9932 | AJ51: 51.49954 | AK51: 32 | AL51: 401 | AM51: 07 | AN51: CONTADO
A52: NO | B52: SUZR | C52: 28/02/2026 | E52: 000001325 | F52: 006-505 | G52: FACTURA CONTADO | H52: 2802202601189171221500120065050000013255658032313 | I52: 18XXXXXXX2001 | J52: 38567 | K52: )!|lTLW_1)%t\T_g91-|d\goA95%l | M52: NO | P52: 2 | R52: 5.49 | T52: 0 | V52: 5.49 | W52: 0 | X52: 5.49 | Y52: 0 | Z52: 0.82 | AA52: 0 | AB52: 0 | AC52: 0 | AD52: 6.31 | AE52: 0 | AF52: 0 | AG52: 3.6234862 | AH52: 1.8665135 | AI52: 33.99843 | AJ52: 51.51154 | AK52: 32 | AL52: 401 | AM52: 07 | AN52: CONTADO
A53: NO | B53: SZRR | C53: 02/02/2026 | E53: 000000244 | F53: 007-505 | G53: FACTURA CREDITO | H53: 0202202601189171221500120075050000002445658032316 | I53: 17XXXXXXX3001 | J53: 28101 | K53: !Cc6{W(=)Kk>$_0E1SsF,g | M53: NO | P53: 2 | R53: 873.63 | T53: 129.58 | V53: 744.05 | W53: 0 | X53: 744.05 | Y53: 0 | Z53: 111.61 | AA53: 0 | AB53: 0 | AC53: 0 | AD53: 855.66 | AE53: 0 | AF53: 0 | AG53: 530.3 | AH53: 213.75 | AI53: 28.72791 | AJ53: 40.307373 | AK53: 32 | AL53: 382 | AM53: 08 | AN53: CREDITO
A54: NO | B54: SZRR | C54: 03/02/2026 | E54: 000000245 | F54: 007-505 | G54: FACTURA CREDITO | H54: 0302202601189171221500120075050000002455658032316 | I54: 18XXXXXXX0001 | J54: 35519 | K54: 87SP7C,T@?[X?K4\HGc`GS<dPOkhO[ | M54: NO | P54: 1 | R54: 250 | T54: 0 | V54: 250 | W54: 0 | X54: 250 | Y54: 0 | Z54: 37.5 | AA54: 0 | AB54: 0 | AC54: 0 | AD54: 287.5 | AE54: 0 | AF54: 0 | AG54: 173.9 | AH54: 76.100006 | AI54: 30.440002 | AJ54: 43.760788 | AK54: 32 | AL54: 383 | AM54: 08 | AN54: CREDITO
A55: NO | B55: SZRR | C55: 04/02/2026 | E55: 000000246 | F55: 007-505 | G55: FACTURA CREDITO | H55: 0402202601189171221500120075050000002465658032316 | I55: 18XXXXXXX0001 | J55: 35519 | K55: f@T*fj/ZnH\2nr7bvPd:vz?j~XlB~# | M55: NO | P55: 1 | R55: 243.48 | T55: 0 | V55: 243.48 | W55: 0 | X55: 243.48 | Y55: 0 | Z55: 36.52 | AA55: 0 | AB55: 0 | AC55: 0 | AD55: 280 | AE55: 0 | AF55: 0 | AG55: 194.92625 | AH55: 48.55374 | AI55: 19.941572 | AJ55: 24.908775 | AK55: 32 | AL55: 384 | AM55: 08 | AN55: CREDITO
A56: NO | B56: SZRR | C56: 11/02/2026 | E56: 000000252 | F56: 007-505 | G56: FACTURA CREDITO | H56: 1102202601189171221500120075050000002525658032319 | I56: 17XXXXXXX3001 | J56: 28101 | K56: 5~R-tPGI='Z5|XOQE/b=%` | M56: NO | P56: 2 | R56: 873.63 | T56: 129.58 | V56: 744.05 | W56: 0 | X56: 744.05 | Y56: 0 | Z56: 111.61 | AA56: 0 | AB56: 0 | AC56: 0 | AD56: 855.66 | AE56: 0 | AF56: 0 | AG56: 530.3 | AH56: 213.75 | AI56: 28.72791 | AJ56: 40.307373 | AK56: 32 | AL56: 389 | AM56: 08 | AN56: CREDITO
A57: NO | B57: SUZR | C57: 19/02/2026 | E57: 000001313 | F57: 006-505 | G57: FACTURA CREDITO | H57: 1902202601189171221500120065050000013135658032319 | I57: 18XXXXXXX6001 | J57: 131041 | K57: \p`7GRH]dxh?OZPel!pGWbXmt)xO_j | M57: NO | P57: 13 | R57: 2387.75 | T57: 238.78 | V57: 2148.97 | W57: 0 | X57: 2148.97 | Y57: 0 | Z57: 322.35 | AA57: 0 | AB57: 0 | AC57: 0 | AD57: 2471.32 | AE57: 0 | AF57: 0 | AG57: 1560.7571 | AH57: 588.21277 | AI57: 27.371847 | AJ57: 37.687653 | AK57: 32 | AL57: 394 | AM57: 07 | AN57: CREDITO
A58: NO | B58: SZRR | C58: 24/02/2026 | E58: 000000255 | F58: 007-505 | G58: FACTURA CREDITO | H58: 2402202601189171221500120075050000002555658032312 | I58: 18XXXXXXX0001 | J58: 35519 | K58: 0"|wr3T"8*% z;\*@2-(#Cd2H:50+K | M58: NO | P58: 1 | R58: 39.13 | T58: 0 | V58: 39.13 | W58: 0 | X58: 39.13 | Y58: 0 | Z58: 5.87 | AA58: 0 | AB58: 0 | AC58: 0 | AD58: 45 | AE58: 0 | AF58: 0 | AG58: 20.92 | AH58: 18.210001 | AI58: 46.537186 | AJ58: 87.0459 | AK58: 32 | AL58: 397 | AM58: 08 | AN58: CREDITO
A59: NO | B59: SUZR | C59: 24/02/2026 | E59: 000001316 | F59: 006-505 | G59: FACTURA CREDITO | H59: 2402202601189171221500120065050000013165658032316 | I59: 18XXXXXXX6001 | J59: 131041 | K59: &3*c_F'].;2kgN/e6C:soV7m>KB{w^ | M59: NO | P59: 1 | R59: 181.11 | T59: 9.06 | V59: 172.05 | W59: 0 | X59: 172.05 | Y59: 0 | Z59: 25.81 | AA59: 0 | AB59: 0 | AC59: 0 | AD59: 197.86 | AE59: 0 | AF59: 0 | AG59: 119.53 | AH59: 52.520004 | AI59: 30.526012 | AJ59: 43.938766 | AK59: 32 | AL59: 397 | AM59: 07 | AN59: CREDITO
A60: NO | B60: SUZR | C60: 26/02/2026 | E60: 000001320 | F60: 006-505 | G60: FACTURA CREDITO | H60: 2602202601189171221500120065050000013205658032317 | I60: 18XXXXXXX0001 | J60: 35519 | K60: (:jOg'`a0BrWo/hi8Jz_w7pq@R#g ? | M60: NO | P60: 2 | R60: 148.36 | T60: 0 | V60: 148.36 | W60: 0 | X60: 148.36 | Y60: 0 | Z60: 22.25 | AA60: 0 | AB60: 0 | AC60: 0 | AD60: 170.61 | AE60: 0 | AF60: 0 | AG60: 97.467212 | AH60: 50.89279 | AI60: 34.303577 | AJ60: 52.215298 | AK60: 32 | AL60: 399 | AM60: 07 | AN60: CREDITO
A61: NO | B61: SUZR | C61: 27/02/2026 | E61: 000001323 | F61: 006-505 | G61: FACTURA CREDITO | H61: 2702202601189171221500120065050000013235658032318 | I61: 18XXXXXXX0001 | J61: 35519 | K61: 2`2*ZZ">:h:2bb*FBpB:jj2NJxJBrr | M61: NO | P61: 1 | R61: 25.65 | T61: 0 | V61: 25.65 | W61: 0 | X61: 25.65 | Y61: 0 | Z61: 3.85 | AA61: 0 | AB61: 0 | AC61: 0 | AD61: 29.5 | AE61: 0 | AF61: 0 | AG61: 17.014074 | AH61: 8.635925 | AI61: 33.668324 | AJ61: 50.757538 | AK61: 32 | AL61: 400 | AM61: 07 | AN61: CREDITO
L63: TOTAL GENERAL: | P63: 12374.95 | R63: 908.17 | T63: 11466.78 | V63: 0 | W63: 11466.78 | X63: 1720.05 | Y63: 0 | AA63: 0 | AB63: 13186.83 | AC63: 0 | AD63: 0 | AE63: 5823.28 | AF63: 8277.486 | AG63: 8277.486 | AH63: 3189.292 | AI63: 27.813334 | AJ63: 38.52974
N64: MAYOR | P64: =+'MY REP SZK'!I31 | R64: =+'MY REP SZK'!H50

Sheet NC REP SZK
B1: TOYOTASERVICIOS S.A. | F1: DEVOLUCIÓN DE VENTAS
B2: REPUESTOS | AC2: Fecha: | AE2: 46085.754
B3: FECHA INICIAL: 01/02/2026
AC4: RepLibroDevolucionesGeneralCB
A5: FECHA FINAL: 28/02/2026
A7: ANULADA | C7: BODEGA | D7: FECHA NC | E7: CODIGO | G7: AGENCIA | H7: SERIE | I7: N/C No. | J7: DEV. A FAC. | K7: DESCRIPCION | L7: AUTORIZACION | N7: FECHA FACT | O7: TOt FACT | P7: CEDULA | R7: COD CLI | T7: CLIENTE | U7: CLIENTE PUBLICO | V7: ITEM | W7: SUBTOT | X7: DESC | Y7: NETO | Z7: SIN IVA | AA7: CON IVA | AB7: ECOVALOR | AD7: VAL. IVA | AF7: OTR.CAR | AG7: INTERES | AH7: TRANSPORTE | AJ7: TOT. NC | AK7: ANTICIPO | AL7: S/NOTA CR | AM7: COSTO | AN7: UTILIDAD | AO7: ASIENTO | AP7: FORMA PAGO
AF8: 0 | AG8: 0 | AH8: 0 | AJ8: 855.66 | AK8: 0 | AM8: 530.3 | AN8: 325.36 | AO8: 389 | AP8: CONTADO
AF9: 0 | AG9: 0 | AH9: 0 | AJ9: 287.48 | AK9: 0 | AM9: 221 | AN9: 66.48001 | AO9: 391 | AP9: CONTADO
M10: TOTAL GENERAL: | V10: 0 | W10: 0 | X10: 0 | Y10: 0 | Z10: 0 | AA10: 0 | AB10: 0 | AD10: 0 | AG10: 0 | AH10: 0 | AJ10: 1143.14 | AK10: 0 | AM10: 751.3 | AN10: 391.84
V11: MAYOR | W11: =+'MY REP SZK'!H55 -> 1136.77 | X11: =+'MY REP SZK'!I50 -> 142.74

Sheet MY REP SZK
A1: CUENTA | B1: NOMBRE | C1: N/M | D1: FECHA | E1: TIPO | F1: NO. | G1: DETALLE | H1: DEBITO | I1: CREDITO | J1: SALDO
A2: 04.01.01.04.0001 | B2: VTAS RPTOS SUZUKI - CONTADO CON IVA | C2: N | D2: 46055.208 | E2: REPTO | F2: 382 | G2: MOD. REPUESTOS REP07 | H2: 0 | I2: 27.86 | J2: -9031.26
A3: 04.01.01.04.0001 | B3: VTAS RPTOS SUZUKI - CONTADO CON IVA | C3: N | D3: 46056.208 | E3: REPTO | F3: 383 | G3: MOD. REPUESTOS REP07 | H3: 0 | I3: 388.38 | J3: -9419.64
A4: 04.01.01.04.0001 | B4: VTAS RPTOS SUZUKI - CONTADO CON IVA | C4: N | D4: 46057.208 | E4: REPTO | F4: 384 | G4: MOD. REPUESTOS REP07 | H4: 0 | I4: 3130.2 | J4: -12549.84
A5: 04.01.01.04.0001 | B5: VTAS RPTOS SUZUKI - CONTADO CON IVA | C5: N | D5: 46057.208 | E5: REPTO | F5: 384 | G5: MOD. REPUESTOS REP08 | H5: 0 | I5: 33.99 | J5: -12583.83
A6: 04.01.01.04.0001 | B6: VTAS RPTOS SUZUKI - CONTADO CON IVA | C6: N | D6: 46059.208 | E6: REPTO | F6: 385 | G6: MOD. REPUESTOS REP07 | H6: 0 | I6: 697.35 | J6: -13281.18
A7: 04.01.01.04.0001 | B7: VTAS RPTOS SUZUKI - CONTADO CON IVA | C7: N | D7: 46060.208 | E7: REPTO | F7: 386 | G7: MOD. REPUESTOS REP08 | H7: 0 | I7: 20 | J7: -13301.18
A8: 04.01.01.04.0001 | B8: VTAS RPTOS SUZUKI - CONTADO CON IVA | C8: N | D8: 46062.208 | E8: REPTO | F8: 387 | G8: MOD. REPUESTOS REP07 | H8: 0 | I8: 289.66 | J8: -13590.84
A9: 04.01.01.04.0001 | B9: VTAS RPTOS SUZUKI - CONTADO CON IVA | C9: N | D9: 46062.208 | E9: REPTO | F9: 387 | G9: MOD. REPUESTOS REP08 | H9: 0 | I9: 30.43 | J9: -13621.27
A10: 04.01.01.04.0001 | B10: VTAS RPTOS SUZUKI - CONTADO CON IVA | C10: N | D10: 46063.208 | E10: REPTO | F10: 388 | G10: MOD. REPUESTOS REP07 | H10: 0 | I10: 119.61 | J10: -13740.88
A11: 04.01.01.04.0001 | B11: VTAS RPTOS SUZUKI - CONTADO CON IVA | C11: N | D11: 46064.208 | E11: REPTO | F11: 389 | G11: MOD. REPUESTOS REP07 | H11: 0 | I11: 6.09 | J11: -13746.97
A12: 04.01.01.04.0001 | B12: VTAS RPTOS SUZUKI - CONTADO CON IVA | C12: N | D12: 46065.208 | E12: REPTO | F12: 390 | G12: MOD. REPUESTOS REP07 | H12: 0 | I12: 272.36 | J12: -14019.33
A13: 04.01.01.04.0001 | B13: VTAS RPTOS SUZUKI - CONTADO CON IVA | C13: N | D13: 46067.208 | E13: REPTO | F13: 392 | G13: MOD. REPUESTOS REP07 | H13: 0 | I13: 144.74 | J13: -14164.07
... A30: 04.01.01.04.0003 | B30: VTAS RPTOS SUZUKI - CREDITO CON IVA | C30: N | D30: 46080.208 | E30: REPTO | F30: 400 | G30: MOD. REPUESTOS REP07 | H30: 0 | I30: 25.65 | J30: -6407.7
I31: =SUM(I2:I30) -> 12374.95
A34: 04.01.01.04.0005 | B34: DESC VTAS RPTOS SUZUKI CONTADO CON IVA | C34: N | D34: 46056.208 | E34: REPTO | F34: 383 | G34: MOD. REPUESTOS REP07 | H34: 11.49 | I34: 0 | J34: 495.7
A35: 04.01.01.04.0005 | B35: DESC VTAS RPTOS SUZUKI CONTADO CON IVA | C35: N | D35: 46057.208 | E35: REPTO | F35: 384 | G35: MOD. REPUESTOS REP07 | H35: 278.21 | I35: 0 | J35: 773.91
A36: 04.01.01.04.0005 | B36: DESC VTAS RPTOS SUZUKI CONTADO CON IVA | C36: N | D36: 46062.208 | E36: REPTO | F36: 387 | G36: MOD. REPUESTOS REP07 | H36: 13.16 | I36: 0 | J36: 787.07
A37: 04.01.01.04.0005 | B37: DESC VTAS RPTOS SUZUKI CONTADO CON IVA | C37: N | D37: 46063.208 | E37: REPTO | F37: 388 | G37: MOD. REPUESTOS REP07 | H37: 7.84 | I37: 0 | J37: 794.91
A38: 04.01.01.04.0005 | B38: DESC VTAS RPTOS SUZUKI CONTADO CON IVA | C38: N | D38: 46065.208 | E38: REPTO | F38: 390 | G38: MOD. REPUESTOS REP07 | H38: 2.86 | I38: 0 | J38: 797.77
A39: 04.01.01.04.0005 | B39: DESC VTAS RPTOS SUZUKI CONTADO CON IVA | C39: N | E39: REPTO | H39: 0 | I39: 0 | J39: 797.77
A40: 04.01.01.04.0005 | B40: DESC VTAS RPTOS SUZUKI CONTADO CON IVA | C40: N | D40: 46067.208 | E40: REPTO | F40: 392 | G40: MOD. REPUESTOS REP07 | H40: 12.94 | I40: 0 | J40: 810.71
A41: 04.01.01.04.0005 | B41: DESC VTAS RPTOS SUZUKI CONTADO CON IVA | C41: N | D41: 46071.208 | E41: REPTO | F41: 393 | G41: MOD. REPUESTOS REP07 | H41: 2.17 | I41: 0 | J41: 812.88
A42: 04.01.01.04.0005 | B42: DESC VTAS RPTOS SUZUKI CONTADO CON IVA | C42: N | D42: 46071.208 | E42: REPTO | F42: 393 | G42: MOD. REPUESTOS REP08 | H42: 43.01 | I42: 0 | J42: 855.89
A43: 04.01.01.04.0005 | B43: DESC VTAS RPTOS SUZUKI CONTADO CON IVA | C43: N | D43: 46074.208 | E43: REPTO | F43: 395 | G43: MOD. REPUESTOS REP07 | H43: 13 | I43: 0 | J43: 868.89
A44: 04.01.01.04.0005 | B44: DESC VTAS RPTOS SUZUKI CONTADO CON IVA | C44: N | D44: 46077.208 | E44: REPTO | F44: 397 | G44: MOD. REPUESTOS REP07 | H44: 16.49 | I44: 0 | J44: 885.38
A45: 04.01.01.04.0007 | B45: DESC VTAS RPTOS SUZUKI CREDITO CON IVA | C45: N | D45: 46055.208 | E45: REPTO | F45: 382 | G45: MOD. REPUESTOS REP08 | H45: 129.58 | I45: 0 | J45: 184.91
A46: 04.01.01.04.0007 | B46: DESC VTAS RPTOS SUZUKI CREDITO CON IVA | C46: N | D46: 46064.208 | E46: REPTO | F46: 389 | G46: MOD. REPUESTOS REP08 | H46: 129.58 | I46: 0 | J46: 314.49
A47: 04.01.01.04.0007 | B47: DESC VTAS RPTOS SUZUKI CREDITO CON IVA | C47: N | E47: REPTO | H47: 0 | I47: 0 | J47: 314.49
